Workbook

Sheet Start Here
B2: The Film Watch Guide
B3: An ordered map of cinema by category, subcategory, and niche. It draws on film-studies textbooks, critics' polls, labels/curators (Criterion, Arrow, BFI, Masters of Cinema, Second Run, the World Cinema Project), and your own Letterboxd history, which is used only to mark what you've seen.
B5: At a glance
B6: Unique films | C6: =COUNTA('Master List'!A2:A2594) -> 2593
B7: Seen (from Letterboxd) | C7: =SUM('Master List'!G2:G2594) -> 411
B8: % seen | C8: =IF(C6=0,0,C7/C6) -> 0.15850366
B9: Watch-path entries (a film can sit in many buckets) | C9: =COUNTA('Watch Paths'!G2:G4220) -> 4219
B10: Categories / subcategories / niches | C10: 10 / 68 / 330
B12: How the tabs work
B13: Dashboard | C13: Progress by category and subcategory. The bars fill in as you log films on Letterboxd.
B14: Priority Queue | C14: Every film ranked by how central it is across the whole map (weighted bucket count). Filter Seen = blank, then work down the list for the best overall order.
B15: Watch Paths | C15: The main list: every category → subcategory → niche in recommended viewing order (Step). '▶ NEXT' marks the first unseen film in each niche. Filter by Category, Niche, or Tier.
B16: Taxonomy | C16: One row per niche: its academic/critical sources, why it's grouped, your progress, and your next film.
B17: Master List | C17: One row per unique film, with every bucket it belongs to and a Letterboxd link.
B18: Bibliography | C18: The books, essays, polls, and label catalogs behind the groupings.
B19: Letterboxd Watched | C19: Your watched.csv. To refresh, paste a newer export's Date/Name/Year/URI into columns A–D. Column E rebuilds the match key, and every Seen mark updates.
B21: How the ordering works
B22: Tier 1 · Start Here | C22: The gateway films for a niche: canonical, accessible, and they teach you how to watch the rest.
B23: Tier 2 · Core | C23: The essential body of the niche, mostly in chronological or influence order, so you can see the style develop.
B24: Tier 3 · Deep Cut | C24: Rarer, harder, or more specialized titles for once the niche clicks.
B25: Step | C25: The recommended order within a niche. Movement/era niches are chronological. Genre and auteur niches go gateway → chronology → deep cuts.
B26: Multiple buckets | C26: Films deliberately appear in many niches (Vertigo sits in history, Hitchcock, theory, canons…). The Priority Queue turns that overlap into a centrality score.
B27: Suggested route | C27: (1) Foundations → (2) History Spine, alongside (5) Auteurs and (4) Genres by mood → (3) World Cinemas → (6) Theory lenses once you want a vocabulary. Dip into (7) Themes, (8) Niches, (9) Canons, and (10) Bridges whenever you like.
B28: Legend | C28: ✓ = logged on your Letterboxd. ▶ NEXT = first unseen film in that niche. Green rows = seen.
B29: Source note | C29: Poll and list selections (S&S 2022, AFI 2007, BFI 100, Ebert) are subsets shown in viewing order, not rank. Label entries (Arrow, BFI Flipside, Masters of Cinema, Second Run) describe each label's catalog focus; editions go in and out of print, so check the label for current releases. 'Composite' curricula are built from standard textbooks, not any single university's syllabus.

Sheet Dashboard
B2: Progress Dashboard
B3: Unique films per category. A film counts once per category even if it's in several of its niches.
B5: Category | C5: Unique Films | D5: Seen | E5: % Seen | F5: Niches | G5: Niches Complete
B6: 01 Foundations: Learning to Watch | C6: =COUNTIF('Master List'!$N$2:$N$2594,1) -> 84 | D6: =COUNTIFS('Master List'!$N$2:$N$2594,1,'Master List'!$G$2:$G$2594,1) -> 40 | E6: =IF(C6=0,0,D6/C6) -> 0.47619048 | F6: =COUNTIF(Taxonomy!$B$2:$B$331,B6) -> 8 | G6: =COUNTIFS(Taxonomy!$B$2:$B$331,B6,Taxonomy!$G$2:$G$331,1) -> 0
B7: 02 Film History Spine (chronological) | C7: =COUNTIF('Master List'!$O$2:$O$2594,1) -> 251 | D7: =COUNTIFS('Master List'!$O$2:$O$2594,1,'Master List'!$G$2:$G$2594,1) -> 68 | E7: =IF(C7=0,0,D7/C7) -> 0.27091633 | F7: =COUNTIF(Taxonomy!$B$2:$B$331,B7) -> 19 | G7: =COUNTIFS(Taxonomy!$B$2:$B$331,B7,Taxonomy!$G$2:$G$331,1) -> 0
B8: 03 World Cinemas & Movements | C8: =COUNTIF('Master List'!$P$2:$P$2594,1) -> 646 | D8: =COUNTIFS('Master List'!$P$2:$P$2594,1,'Master List'!$G$2:$G$2594,1) -> 24 | E8: =IF(C8=0,0,D8/C8) -> 0.037151703 | F8: =COUNTIF(Taxonomy!$B$2:$B$331,B8) -> 56 | G8: =COUNTIFS(Taxonomy!$B$2:$B$331,B8,Taxonomy!$G$2:$G$331,1) -> 0
B9: 04 Genres & Subgenres | C9: =COUNTIF('Master List'!$Q$2:$Q$2594,1) -> 821 | D9: =COUNTIFS('Master List'!$Q$2:$Q$2594,1,'Master List'!$G$2:$G$2594,1) -> 165 | E9: =IF(C9=0,0,D9/C9) -> 0.20097442 | F9: =COUNTIF(Taxonomy!$B$2:$B$331,B9) -> 72 | G9: =COUNTIFS(Taxonomy!$B$2:$B$331,B9,Taxonomy!$G$2:$G$331,1) -> 0
B10: 05 Auteurs & Filmographies | C10: =COUNTIF('Master List'!$R$2:$R$2594,1) -> 781 | D10: =COUNTIFS('Master List'!$R$2:$R$2594,1,'Master List'!$G$2:$G$2594,1) -> 205 | E10: =IF(C10=0,0,D10/C10) -> 0.26248399 | F10: =COUNTIF(Taxonomy!$B$2:$B$331,B10) -> 67 | G10: =COUNTIFS(Taxonomy!$B$2:$B$331,B10,Taxonomy!$G$2:$G$331,1) -> 2
B11: 06 Theory & Academic Lenses | C11: =COUNTIF('Master List'!$S$2:$S$2594,1) -> 256 | D11: =COUNTIFS('Master List'!$S$2:$S$2594,1,'Master List'!$G$2:$G$2594,1) -> 48 | E11: =IF(C11=0,0,D11/C11) -> 0.1875 | F11: =COUNTIF(Taxonomy!$B$2:$B$331,B11) -> 22 | G11: =COUNTIFS(Taxonomy!$B$2:$B$331,B11,Taxonomy!$G$2:$G$331,1) -> 0
B12: 07 Themes & Subjects | C12: =COUNTIF('Master List'!$T$2:$T$2594,1) -> 422 | D12: =COUNTIFS('Master List'!$T$2:$T$2594,1,'Master List'!$G$2:$G$2594,1) -> 114 | E12: =IF(C12=0,0,D12/C12) -> 0.27014218 | F12: =COUNTIF(Taxonomy!$B$2:$B$331,B12) -> 31 | G12: =COUNTIFS(Taxonomy!$B$2:$B$331,B12,Taxonomy!$G$2:$G$331,1) -> 0
B13: 08 Niches & Micro-genres | C13: =COUNTIF('Master List'!$U$2:$U$2594,1) -> 281 | D13: =COUNTIFS('Master List'!$U$2:$U$2594,1,'Master List'!$G$2:$G$2594,1) -> 63 | E13: =IF(C13=0,0,D13/C13) -> 0.22419929 | F13: =COUNTIF(Taxonomy!$B$2:$B$331,B13) -> 25 | G13: =COUNTIFS(Taxonomy!$B$2:$B$331,B13,Taxonomy!$G$2:$G$331,1) -> 0
B14: 09 Canons, Critics, Labels & Curricula | C14: =COUNTIF('Master List'!$V$2:$V$2594,1) -> 298 | D14: =COUNTIFS('Master List'!$V$2:$V$2594,1,'Master List'!$G$2:$G$2594,1) -> 79 | E14: =IF(C14=0,0,D14/C14) -> 0.26510067 | F14: =COUNTIF(Taxonomy!$B$2:$B$331,B14) -> 16 | G14: =COUNTIFS(Taxonomy!$B$2:$B$331,B14,Taxonomy!$G$2:$G$331,1) -> 0
B15: 10 Bridges From Your 5-Star Films | C15: =COUNTIF('Master List'!$W$2:$W$2594,1) -> 139 | D15: =COUNTIFS('Master List'!$W$2:$W$2594,1,'Master List'!$G$2:$G$2594,1) -> 41 | E15: =IF(C15=0,0,D15/C15) -> 0.29496403 | F15: =COUNTIF(Taxonomy!$B$2:$B$331,B15) -> 14 | G15: =COUNTIFS(Taxonomy!$B$2:$B$331,B15,Taxonomy!$G$2:$G$331,1) -> 0
B16: All films (unique) | C16: =COUNTA('Master List'!A2:A2594) -> 2593 | D16: =SUM('Master List'!G2:G2594) -> 411 | E16: =IF(C16=0,0,D16/C16) -> 0.15850366 | F16: =SUM(F6:F15) -> 330 | G16: =SUM(G6:G15) -> 2
B18: By subcategory (watch-path entries)
B19: Category | C19: Subcategory | D19: Entries | E19: Seen | F19: % Seen | G19: Niches
B20: 01 Foundations: Learning to Watch | C20: Film Form (the Film Art method) | D20: =COUNTIFS('Watch Paths'!$B$2:$B$4220,B20,'Watch Paths'!$C$2:$C$4220,C20) -> 70 | E20: =COUNTIFS('Watch Paths'!$B$2:$B$4220,B20,'Watch Paths'!$C$2:$C$4220,C20,'Watch Paths'!$M$2:$M$4220,1) -> 32 | F20: =IF(D20=0,0,E20/D20) -> 0.45714286 | G20: =COUNTIFS(Taxonomy!$B$2:$B$331,B20,Taxonomy!$C$2:$C$331,C20) -> 6
B21: 01 Foundations: Learning to Watch | C21: Narrative & Structure | D21: =COUNTIFS('Watch Paths'!$B$2:$B$4220,B21,'Watch Paths'!$C$2:$C$4220,C21) -> 20 | E21: =COUNTIFS('Watch Paths'!$B$2:$B$4220,B21,'Watch Paths'!$C$2:$C$4220,C21,'Watch Paths'!$M$2:$M$4220,1) -> 12 | F21: =IF(D21=0,0,E21/D21) -> 0.6 | G21: =COUNTIFS(Taxonomy!$B$2:$B$331,B21,Taxonomy!$C$2:$C$331,C21) -> 2
B22: 02 Film History Spine (chronological) | C22: 1. Silent Era (1895–1929) | D22: =COUNTIFS('Watch Paths'!$B$2:$B$4220,B22,'Watch Paths'!$C$2:$C$4220,C22) -> 73 | E22: =COUNTIFS('Watch Paths'!$B$2:$B$4220,B22,'Watch Paths'!$C$2:$C$4220,C22,'Watch Paths'!$M$2:$M$4220,1) -> 6 | F22: =IF(D22=0,0,E22/D22) -> 0.082191781 | G22: =COUNTIFS(Taxonomy!$B$2:$B$331,B22,Taxonomy!$C$2:$C$331,C22) -> 7
B23: 02 Film History Spine (chronological) | C23: 2. Early Sound & Pre-Code (1927–1934) | D23: =COUNTIFS('Watch Paths'!$B$2:$B$4220,B23,'Watch Paths'!$C$2:$C$4220,C23) -> 24 | E23: =COUNTIFS('Watch Paths'!$B$2:$B$4220,B23,'Watch Paths'!$C$2:$C$4220,C23,'Watch Paths'!$M$2:$M$4220,1) -> 1 | F23: =IF(D23=0,0,E23/D23) -> 0.041666667 | G23: =COUNTIFS(Taxonomy!$B$2:$B$331,B23,Taxonomy!$C$2:$C$331,C23) -> 2
B24: 02 Film History Spine (chronological) | C24: 3. Classical Hollywood (1930–1960) | D24: =COUNTIFS('Watch Paths'!$B$2:$B$4220,B24,'Watch Paths'!$C$2:$C$4220,C24) -> 30 | E24: =COUNTIFS('Watch Paths'!$B$2:$B$4220,B24,'Watch Paths'!$C$2:$C$4220,C24,'Watch Paths'!$M$2:$M$4220,1) -> 6 | F24: =IF(D24=0,0,E24/D24) -> 0.2 | G24: =COUNTIFS(Taxonomy!$B$2:$B$331,B24,Taxonomy!$C$2:$C$331,C24) -> 2
B25: 02 Film History Spine (chronological) | C25: 4. Postwar World Cinema (1945–1959) | D25: =COUNTIFS('Watch Paths'!$B$2:$B$4220,B25,'Watch Paths'!$C$2:$C$4220,C25) -> 14 | E25: =COUNTIFS('Watch Paths'!$B$2:$B$4220,B25,'Watch Paths'!$C$2:$C$4220,C25,'Watch Paths'!$M$2:$M$4220,1) -> 3 | F25: =IF(D25=0,0,E25/D25) -> 0.21428571 | G25: =COUNTIFS(Taxonomy!$B$2:$B$331,B25,Taxonomy!$C$2:$C$331,C25) -> 1
B26: 02 Film History Spine (chronological) | C26: 5. Modernism & the New Waves (1959–1975) | D26: =COUNTIFS('Watch Paths'!$B$2:$B$4220,B26,'Watch Paths'!$C$2:$C$4220,C26) -> 16 | E26: =COUNTIFS('Watch Paths'!$B$2:$B$4220,B26,'Watch Paths'!$C$2:$C$4220,C26,'Watch Paths'!$M$2:$M$4220,1) -> 1 | F26: =IF(D26=0,0,E26/D26) -> 0.0625 | G26: =COUNTIFS(Taxonomy!$B$2:$B$331,B26,Taxonomy!$C$2:$C$331,C26) -> 1
B27: 02 Film History Spine (chronological) | C27: 6. New Hollywood (1967–1980) | D27: =COUNTIFS('Watch Paths'!$B$2:$B$4220,B27,'Watch Paths'!$C$2:$C$4220,C27) -> 22 | E27: =COUNTIFS('Watch Paths'!$B$2:$B$4220,B27,'Watch Paths'!$C$2:$C$4220,C27,'Watch Paths'!$M$2:$M$4220,1) -> 14 | F27: =IF(D27=0,0,E27/D27) -> 0.63636364 | G27: =COUNTIFS(Taxonomy!$B$2:$B$331,B27,Taxonomy!$C$2:$C$331,C27) -> 1
B28: 02 Film History Spine (chronological) | C28: 7. Blockbuster & Reagan Era (1975–1989) | D28: =COUNTIFS('Watch Paths'!$B$2:$B$4220,B28,'Watch Paths'!$C$2:$C$4220,C28) -> 24 | E28: =COUNTIFS('Watch Paths'!$B$2:$B$4220,B28,'Watch Paths'!$C$2:$C$4220,C28,'Watch Paths'!$M$2:$M$4220,1) -> 17 | F28: =IF(D28=0,0,E28/D28) -> 0.70833333 | G28: =COUNTIFS(Taxonomy!$B$2:$B$331,B28,Taxonomy!$C$2:$C$331,C28) -> 2
B29: 02 Film History Spine (chronological) | C29: 8. The Independent Boom (1984–2000) | D29: =COUNTIFS('Watch Paths'!$B$2:$B$4220,B29,'Watch Paths'!$C$2:$C$4220,C29) -> 17 | E29: =COUNTIFS('Watch Paths'!$B$2:$B$4220,B29,'Watch Paths'!$C$2:$C$4220,C29,'Watch Paths'!$M$2:$M$4220,1) -> 7 | F29: =IF(D29=0,0,E29/D29) -> 0.41176471 | G29: =COUNTIFS(Taxonomy!$B$2:$B$331,B29,Taxonomy!$C$2:$C$331,C29) -> 1
B30: 02 Film History Spine (chronological) | C30: 9. Digital & Global (2000–2015) | D30: =COUNTIFS('Watch Paths'!$B$2:$B$4220,B30,'Watch Paths'!$C$2:$C$4220,C30) -> 17 | E30: =COUNTIFS('Watch Paths'!$B$2:$B$4220,B30,'Watch Paths'!$C$2:$C$4220,C30,'Watch Paths'!$M$2:$M$4220,1) -> 8 | F30: =IF(D30=0,0,E30/D30) -> 0.47058824 | G30: =COUNTIFS(Taxonomy!$B$2:$B$331,B30,Taxonomy!$C$2:$C$331,C30) -> 1
B31: 02 Film History Spine (chronological) | C31: 10. Streaming & Now (2016–2026) | D31: =COUNTIFS('Watch Paths'!$B$2:$B$4220,B31,'Watch Paths'!$C$2:$C$4220,C31) -> 18 | E31: =COUNTIFS('Watch Paths'!$B$2:$B$4220,B31,'Watch Paths'!$C$2:$C$4220,C31,'Watch Paths'!$M$2:$M$4220,1) -> 5 | F31: =IF(D31=0,0,E31/D31) -> 0.27777778 | G31: =COUNTIFS(Taxonomy!$B$2:$B$331,B31,Taxonomy!$C$2:$C$331,C31) -> 1
... B87: 10 Bridges From Your 5-Star Films | C87: Genre Lines From Your Favorites | D87: =COUNTIFS('Watch Paths'!$B$2:$B$4220,B87,'Watch Paths'!$C$2:$C$4220,C87) -> 62 | E87: =COUNTIFS('Watch Paths'!$B$2:$B$4220,B87,'Watch Paths'!$C$2:$C$4220,C87,'Watch Paths'!$M$2:$M$4220,1) -> 10 | F87: =IF(D87=0,0,E87/D87) -> 0.16129032 | G87: =COUNTIFS(Taxonomy!$B$2:$B$331,B87,Taxonomy!$C$2:$C$331,C87) -> 6

Sheet Priority Queue
A1: Rank | B1: Title | C1: Year | D1: Director | E1: Seen | F1: Centrality Score | G1: Buckets | H1: Best Tier | I1: Primary Category | J1: Seen # | K1: Master Row | M1: Score = Σ over every bucket (Start Here = 3, Core = 2, Deep Cut = 1). Higher means more central to the whole map. Filter Seen = blank and go top-down.
A2: 1 | B2: Citizen Kane | C2: 1941 | D2: Orson Welles | E2: =IF(J2=1,"✓","") | F2: 32 | G2: 13 | H2: 1 · Start Here | I2: 01 Foundations: Learning to Watch | J2: =INDEX('Master List'!$G$2:$G$2594,K2) -> 0 | K2: 462
A3: 2 | B3: Tokyo Story | C3: 1953 | D3: Yasujirō Ozu | E3: =IF(J3=1,"✓","") | F3: 25 | G3: 10 | H3: 1 · Start Here | I3: 01 Foundations: Learning to Watch | J3: =INDEX('Master List'!$G$2:$G$2594,K3) -> 0 | K3: 2328
A4: 3 | B4: Do the Right Thing | C4: 1989 | D4: Spike Lee | E4: =IF(J4=1,"✓","") -> ✓ | F4: 25 | G4: 11 | H4: 1 · Start Here | I4: 01 Foundations: Learning to Watch | J4: =INDEX('Master List'!$G$2:$G$2594,K4) -> 1 | K4: 646
A5: 4 | B5: The 400 Blows | C5: 1959 | D5: François Truffaut | E5: =IF(J5=1,"✓","") | F5: 22 | G5: 8 | H5: 1 · Start Here | I5: 02 Film History Spine (chronological) | J5: =INDEX('Master List'!$G$2:$G$2594,K5) -> 0 | K5: 25
A6: 5 | B6: Breathless | C6: 1960 | D6: Jean-Luc Godard | E6: =IF(J6=1,"✓","") | F6: 21 | G6: 9 | H6: 1 · Start Here | I6: 01 Foundations: Learning to Watch | J6: =INDEX('Master List'!$G$2:$G$2594,K6) -> 0 | K6: 342
A7: 6 | B7: Mulholland Drive | C7: 2001 | D7: David Lynch | E7: =IF(J7=1,"✓","") -> ✓ | F7: 20 | G7: 9 | H7: 1 · Start Here | I7: 01 Foundations: Learning to Watch | J7: =INDEX('Master List'!$G$2:$G$2594,K7) -> 1 | K7: 1555
A8: 7 | B8: Seven Samurai | C8: 1954 | D8: Akira Kurosawa | E8: =IF(J8=1,"✓","") | F8: 20 | G8: 8 | H8: 1 · Start Here | I8: 02 Film History Spine (chronological) | J8: =INDEX('Master List'!$G$2:$G$2594,K8) -> 0 | K8: 2021
A9: 8 | B9: Cléo from 5 to 7 | C9: 1962 | D9: Agnès Varda | E9: =IF(J9=1,"✓","") | F9: 19 | G9: 7 | H9: 1 · Start Here | I9: 02 Film History Spine (chronological) | J9: =INDEX('Master List'!$G$2:$G$2594,K9) -> 0 | K9: 475
A10: 9 | B10: Bicycle Thieves | C10: 1948 | D10: Vittorio De Sica | E10: =IF(J10=1,"✓","") | F10: 19 | G10: 7 | H10: 1 · Start Here | I10: 02 Film History Spine (chronological) | J10: =INDEX('Master List'!$G$2:$G$2594,K10) -> 0 | K10: 238
A11: 10 | B11: Vertigo | C11: 1958 | D11: Alfred Hitchcock | E11: =IF(J11=1,"✓","") | F11: 19 | G11: 7 | H11: 1 · Start Here | I11: 02 Film History Spine (chronological) | J11: =INDEX('Master List'!$G$2:$G$2594,K11) -> 0 | K11: 2429
A12: 11 | B12: Taxi Driver | C12: 1976 | D12: Martin Scorsese | E12: =IF(J12=1,"✓","") -> ✓ | F12: 19 | G12: 8 | H12: 1 · Start Here | I12: 02 Film History Spine (chronological) | J12: =INDEX('Master List'!$G$2:$G$2594,K12) -> 1 | K12: 2248
A13: 12 | B13: Moonlight | C13: 2016 | D13: Barry Jenkins | E13: =IF(J13=1,"✓","") -> ✓ | F13: 19 | G13: 8 | H13: 1 · Start Here | I13: 02 Film History Spine (chronological) | J13: =INDEX('Master List'!$G$2:$G$2594,K13) -> 1 | K13: 1532
... A2594: 2593 | B2594: Nouvelle Vague | C2594: 2025 | D2594: Richard Linklater | E2594: =IF(J2594=1,"✓","") | F2594: 1 | G2594: 1 | H2594: 3 · Deep Cut | I2594: 05 Auteurs & Filmographies | J2594: =INDEX('Master List'!$G$2:$G$2594,K2594) -> 0 | K2594: 1640

Sheet Watch Paths
A1: Niche ID | B1: Category | C1: Subcategory | D1: Niche | E1: Step | F1: Tier | G1: Title | H1: Year | I1: Director | J1: Seen | K1: Next Up | L1: Buckets | M1: Seen # | N1: Next ID | O1: Master Row | P1: Unseen Before
A2: N001 | B2: 01 Foundations: Learning to Watch | C2: Film Form (the Film Art method) | D2: Critical-analysis films from Film Art | E2: 1 | F2: 1 · Start Here | G2: His Girl Friday | H2: 1940 | I2: Howard Hawks | J2: =IF(M2=1,"✓","") -> ✓ | K2: =IF(AND(M2=0,P2=0),"▶ NEXT","") | L2: =INDEX('Master List'!$F$2:$F$2594,O2) -> 7 | M2: =INDEX('Master List'!$G$2:$G$2594,O2) -> 1 | N2: =IF(K2="","",A2) | O2: 1041 | P2: 0
A3: N001 | B3: 01 Foundations: Learning to Watch | C3: Film Form (the Film Art method) | D3: Critical-analysis films from Film Art | E3: 2 | F3: 1 · Start Here | G3: North by Northwest | H3: 1959 | I3: Alfred Hitchcock | J3: =IF(M3=1,"✓","") | K3: =IF(AND(M3=0,P3=0),"▶ NEXT","") -> ▶ NEXT | L3: =INDEX('Master List'!$F$2:$F$2594,O3) -> 3 | M3: =INDEX('Master List'!$G$2:$G$2594,O3) -> 0 | N3: =IF(K3="","",A3) -> N001 | O3: 1630 | P3: =IF(A3=A2,P2+1-M2,0) -> 0
A4: N001 | B4: 01 Foundations: Learning to Watch | C4: Film Form (the Film Art method) | D4: Critical-analysis films from Film Art | E4: 3 | F4: 1 · Start Here | G4: Do the Right Thing | H4: 1989 | I4: Spike Lee | J4: =IF(M4=1,"✓","") -> ✓ | K4: =IF(AND(M4=0,P4=0),"▶ NEXT","") | L4: =INDEX('Master List'!$F$2:$F$2594,O4) -> 11 | M4: =INDEX('Master List'!$G$2:$G$2594,O4) -> 1 | N4: =IF(K4="","",A4) | O4: 646 | P4: =IF(A4=A3,P3+1-M3,0) -> 1
A5: N001 | B5: 01 Foundations: Learning to Watch | C5: Film Form (the Film Art method) | D5: Critical-analysis films from Film Art | E5: 4 | F5: 2 · Core | G5: Breathless | H5: 1960 | I5: Jean-Luc Godard | J5: =IF(M5=1,"✓","") | K5: =IF(AND(M5=0,P5=0),"▶ NEXT","") | L5: =INDEX('Master List'!$F$2:$F$2594,O5) -> 9 | M5: =INDEX('Master List'!$G$2:$G$2594,O5) -> 0 | N5: =IF(K5="","",A5) | O5: 342 | P5: =IF(A5=A4,P4+1-M4,0) -> 1
A6: N001 | B6: 01 Foundations: Learning to Watch | C6: Film Form (the Film Art method) | D6: Critical-analysis films from Film Art | E6: 5 | F6: 2 · Core | G6: Tokyo Story | H6: 1953 | I6: Yasujirō Ozu | J6: =IF(M6=1,"✓","") | K6: =IF(AND(M6=0,P6=0),"▶ NEXT","") | L6: =INDEX('Master List'!$F$2:$F$2594,O6) -> 10 | M6: =INDEX('Master List'!$G$2:$G$2594,O6) -> 0 | N6: =IF(K6="","",A6) | O6: 2328 | P6: =IF(A6=A5,P5+1-M5,0) -> 2
A7: N001 | B7: 01 Foundations: Learning to Watch | C7: Film Form (the Film Art method) | D7: Critical-analysis films from Film Art | E7: 6 | F7: 2 · Core | G7: Chungking Express | H7: 1994 | I7: Wong Kar-wai | J7: =IF(M7=1,"✓","") | K7: =IF(AND(M7=0,P7=0),"▶ NEXT","") | L7: =INDEX('Master List'!$F$2:$F$2594,O7) -> 7 | M7: =INDEX('Master List'!$G$2:$G$2594,O7) -> 0 | N7: =IF(K7="","",A7) | O7: 458 | P7: =IF(A7=A6,P6+1-M6,0) -> 3
A8: N001 | B8: 01 Foundations: Learning to Watch | C8: Film Form (the Film Art method) | D8: Critical-analysis films from Film Art | E8: 7 | F8: 2 · Core | G8: Man with a Movie Camera | H8: 1929 | I8: Dziga Vertov | J8: =IF(M8=1,"✓","") | K8: =IF(AND(M8=0,P8=0),"▶ NEXT","") | L8: =INDEX('Master List'!$F$2:$F$2594,O8) -> 7 | M8: =INDEX('Master List'!$G$2:$G$2594,O8) -> 0 | N8: =IF(K8="","",A8) | O8: 1434 | P8: =IF(A8=A7,P7+1-M7,0) -> 4
A9: N001 | B9: 01 Foundations: Learning to Watch | C9: Film Form (the Film Art method) | D9: Critical-analysis films from Film Art | E9: 8 | F9: 2 · Core | G9: Meet Me in St. Louis | H9: 1944 | I9: Vincente Minnelli | J9: =IF(M9=1,"✓","") | K9: =IF(AND(M9=0,P9=0),"▶ NEXT","") | L9: =INDEX('Master List'!$F$2:$F$2594,O9) -> 3 | M9: =INDEX('Master List'!$G$2:$G$2594,O9) -> 0 | N9: =IF(K9="","",A9) | O9: 1473 | P9: =IF(A9=A8,P8+1-M8,0) -> 5
A10: N001 | B10: 01 Foundations: Learning to Watch | C10: Film Form (the Film Art method) | D10: Critical-analysis films from Film Art | E10: 9 | F10: 2 · Core | G10: Raging Bull | H10: 1980 | I10: Martin Scorsese | J10: =IF(M10=1,"✓","") -> ✓ | K10: =IF(AND(M10=0,P10=0),"▶ NEXT","") | L10: =INDEX('Master List'!$F$2:$F$2594,O10) -> 5 | M10: =INDEX('Master List'!$G$2:$G$2594,O10) -> 1 | N10: =IF(K10="","",A10) | O10: 1850 | P10: =IF(A10=A9,P9+1-M9,0) -> 6
A11: N001 | B11: 01 Foundations: Learning to Watch | C11: Film Form (the Film Art method) | D11: Critical-analysis films from Film Art | E11: 10 | F11: 2 · Core | G11: Citizen Kane | H11: 1941 | I11: Orson Welles | J11: =IF(M11=1,"✓","") | K11: =IF(AND(M11=0,P11=0),"▶ NEXT","") | L11: =INDEX('Master List'!$F$2:$F$2594,O11) -> 13 | M11: =INDEX('Master List'!$G$2:$G$2594,O11) -> 0 | N11: =IF(K11="","",A11) | O11: 462 | P11: =IF(A11=A10,P10+1-M10,0) -> 6
A12: N001 | B12: 01 Foundations: Learning to Watch | C12: Film Form (the Film Art method) | D12: Critical-analysis films from Film Art | E12: 11 | F12: 3 · Deep Cut | G12: Our Hospitality | H12: 1923 | I12: Buster Keaton | J12: =IF(M12=1,"✓","") | K12: =IF(AND(M12=0,P12=0),"▶ NEXT","") | L12: =INDEX('Master List'!$F$2:$F$2594,O12) -> 2 | M12: =INDEX('Master List'!$G$2:$G$2594,O12) -> 0 | N12: =IF(K12="","",A12) | O12: 1698 | P12: =IF(A12=A11,P11+1-M11,0) -> 7
A13: N001 | B13: 01 Foundations: Learning to Watch | C13: Film Form (the Film Art method) | D13: Critical-analysis films from Film Art | E13: 12 | F13: 3 · Deep Cut | G13: Day of Wrath | H13: 1943 | I13: Carl Theodor Dreyer | J13: =IF(M13=1,"✓","") | K13: =IF(AND(M13=0,P13=0),"▶ NEXT","") | L13: =INDEX('Master List'!$F$2:$F$2594,O13) -> 2 | M13: =INDEX('Master List'!$G$2:$G$2594,O13) -> 0 | N13: =IF(K13="","",A13) | O13: 576 | P13: =IF(A13=A12,P12+1-M12,0) -> 8
A14: N002 | B14: 01 Foundations: Learning to Watch | C14: Film Form (the Film Art method) | D14: Mise-en-scène & production design | E14: 1 | F14: 1 · Start Here | G14: The Cabinet of Dr. Caligari | H14: 1920 | I14: Robert Wiene | J14: =IF(M14=1,"✓","") | K14: =IF(AND(M14=0,P14=0),"▶ NEXT","") -> ▶ NEXT | L14: =INDEX('Master List'!$F$2:$F$2594,O14) -> 4 | M14: =INDEX('Master List'!$G$2:$G$2594,O14) -> 0 | N14: =IF(K14="","",A14) -> N002 | O14: 377 | P14: =IF(A14=A13,P13+1-M13,0) -> 0
... A4220: N330 | B4220: 10 Bridges From Your 5-Star Films | C4220: Genre Lines From Your Favorites | D4220: Because you loved Everything Everywhere All at Once & Barbie | E4220: 11 | F4220: 3 · Deep Cut | G4220: Swiss Army Man | H4220: 2016 | I4220: Daniel Kwan, Daniel Scheinert | J4220: =IF(M4220=1,"✓","") | K4220: =IF(AND(M4220=0,P4220=0),"▶ NEXT","") | L4220: =INDEX('Master List'!$F$2:$F$2594,O4220) -> 1 | M4220: =INDEX('Master List'!$G$2:$G$2594,O4220) -> 0 | N4220: =IF(K4220="","",A4220) | O4220: 2218 | P4220: =IF(A4220=A4219,P4219+1-M4219,0) -> 8

Sheet Taxonomy
A1: Niche ID | B1: Category | C1: Subcategory | D1: Niche | E1: Films | F1: Seen | G1: % Seen | H1: Next Up | I1: Why this grouping / how to watch it | J1: Academic & critical sources
A2: N001 | B2: 01 Foundations: Learning to Watch | C2: Film Form (the Film Art method) | D2: Critical-analysis films from Film Art | E2: =COUNTIF('Watch Paths'!$A$2:$A$4220,A2) -> 12 | F2: =COUNTIFS('Watch Paths'!$A$2:$A$4220,A2,'Watch Paths'!$M$2:$M$4220,1) -> 3 | G2: =IF(E2=0,0,F2/E2) -> 0.25 | H2: =IFERROR(INDEX('Watch Paths'!$G$2:$G$4220,MATCH(A2,'Watch Paths'!$N$2:$N$4220,0)),"✓ complete") -> North by Northwest | I2: The films the most-assigned intro textbook dissects. Watch each, then read the chapter: classical narrative first, then alternatives, then style-as-ideology. | J2: Bordwell, Thompson & Smith, Film Art: An Introduction (McGraw-Hill; ch. 'Film Criticism: Sample Analyses' — film selection varies by edition)
A3: N002 | B3: 01 Foundations: Learning to Watch | C3: Film Form (the Film Art method) | D3: Mise-en-scène & production design | E3: =COUNTIF('Watch Paths'!$A$2:$A$4220,A3) -> 11 | F3: =COUNTIFS('Watch Paths'!$A$2:$A$4220,A3,'Watch Paths'!$M$2:$M$4220,1) -> 4 | G3: =IF(E3=0,0,F3/E3) -> 0.36363636 | H3: =IFERROR(INDEX('Watch Paths'!$G$2:$G$4220,MATCH(A3,'Watch Paths'!$N$2:$N$4220,0)),"✓ complete") -> The Cabinet of Dr. Caligari | I3: Everything placed in front of the camera. Train your eye on set, costume, staging, and lighting. | J3: Film Art ch. 4; Bazin, What Is Cinema? (1958–62)
A4: N003 | B4: 01 Foundations: Learning to Watch | C4: Film Form (the Film Art method) | D4: Cinematography: light, lens & the moving camera | E4: =COUNTIF('Watch Paths'!$A$2:$A$4220,A4) -> 13 | F4: =COUNTIFS('Watch Paths'!$A$2:$A$4220,A4,'Watch Paths'!$M$2:$M$4220,1) -> 5 | G4: =IF(E4=0,0,F4/E4) -> 0.38461538 | H4: =IFERROR(INDEX('Watch Paths'!$G$2:$G$4220,MATCH(A4,'Watch Paths'!$N$2:$N$4220,0)),"✓ complete") -> Citizen Kane | I4: Deep focus, chiaroscuro, natural light, and the camera as a narrator. | J4: Film Art ch. 5; ASC 'Most Important Cinematographed Films' poll (2019)
A5: N004 | B5: 01 Foundations: Learning to Watch | C5: Film Form (the Film Art method) | D5: Editing: montage vs. continuity | E5: =COUNTIF('Watch Paths'!$A$2:$A$4220,A5) -> 12 | F5: =COUNTIFS('Watch Paths'!$A$2:$A$4220,A5,'Watch Paths'!$M$2:$M$4220,1) -> 6 | G5: =IF(E5=0,0,F5/E5) -> 0.5 | H5: =IFERROR(INDEX('Watch Paths'!$G$2:$G$4220,MATCH(A5,'Watch Paths'!$N$2:$N$4220,0)),"✓ complete") -> Battleship Potemkin | I5: From Griffith's cross-cutting and Soviet collision montage to modern fragmentation. | J5: Film Art ch. 6; Eisenstein, Film Form (1949); Murch, In the Blink of an Eye (1995)
A6: N005 | B6: 01 Foundations: Learning to Watch | C6: Film Form (the Film Art method) | D6: Sound & music | E6: =COUNTIF('Watch Paths'!$A$2:$A$4220,A6) -> 10 | F6: =COUNTIFS('Watch Paths'!$A$2:$A$4220,A6,'Watch Paths'!$M$2:$M$4220,1) -> 8 | G6: =IF(E6=0,0,F6/E6) -> 0.8 | H6: =IFERROR(INDEX('Watch Paths'!$G$2:$G$4220,MATCH(A6,'Watch Paths'!$N$2:$N$4220,0)),"✓ complete") -> Berberian Sound Studio | I6: Diegetic vs. non-diegetic, sound bridges, silence as a tool. | J6: Film Art ch. 7; Chion, Audio-Vision (1990)
A7: N006 | B7: 01 Foundations: Learning to Watch | C7: Film Form (the Film Art method) | D7: The long take & the oner | E7: =COUNTIF('Watch Paths'!$A$2:$A$4220,A7) -> 12 | F7: =COUNTIFS('Watch Paths'!$A$2:$A$4220,A7,'Watch Paths'!$M$2:$M$4220,1) -> 6 | G7: =IF(E7=0,0,F7/E7) -> 0.5 | H7: =IFERROR(INDEX('Watch Paths'!$G$2:$G$4220,MATCH(A7,'Watch Paths'!$N$2:$N$4220,0)),"✓ complete") -> Touch of Evil | I7: Duration as style: tension, realism, and choreography without cuts. | J7: Bazin, 'The Evolution of the Language of Cinema'; Henderson, 'The Long Take' (1971)
A8: N007 | B8: 01 Foundations: Learning to Watch | C8: Narrative & Structure | D8: Non-linear & unreliable narration | E8: =COUNTIF('Watch Paths'!$A$2:$A$4220,A8) -> 11 | F8: =COUNTIFS('Watch Paths'!$A$2:$A$4220,A8,'Watch Paths'!$M$2:$M$4220,1) -> 6 | G8: =IF(E8=0,0,F8/E8) -> 0.54545455 | H8: =IFERROR(INDEX('Watch Paths'!$G$2:$G$4220,MATCH(A8,'Watch Paths'!$N$2:$N$4220,0)),"✓ complete") -> Citizen Kane | I8: How stories withhold, repeat, and lie. A bridge to the Mind-Game lens in Theory. | J8: Bordwell, Narration in the Fiction Film (1985); Buckland (ed.), Puzzle Films (2009)
A9: N008 | B9: 01 Foundations: Learning to Watch | C9: Narrative & Structure | D9: The Hollywood screenplay template | E9: =COUNTIF('Watch Paths'!$A$2:$A$4220,A9) -> 9 | F9: =COUNTIFS('Watch Paths'!$A$2:$A$4220,A9,'Watch Paths'!$M$2:$M$4220,1) -> 6 | G9: =IF(E9=0,0,F9/E9) -> 0.66666667 | H9: =IFERROR(INDEX('Watch Paths'!$G$2:$G$4220,MATCH(A9,'Watch Paths'!$N$2:$N$4220,0)),"✓ complete") -> Casablanca | I9: Model three-act and four-part structures that screenwriting programs teach. | J9: Field, Screenplay (1979); Thompson, Storytelling in the New Hollywood (1999)
A10: N009 | B10: 02 Film History Spine (chronological) | C10: 1. Silent Era (1895–1929) | D10: Cinema of attractions & early narrative (1895–1914) | E10: =COUNTIF('Watch Paths'!$A$2:$A$4220,A10) -> 11 | F10: =COUNTIFS('Watch Paths'!$A$2:$A$4220,A10,'Watch Paths'!$M$2:$M$4220,1) -> 4 | G10: =IF(E10=0,0,F10/E10) -> 0.36363636 | H10: =IFERROR(INDEX('Watch Paths'!$G$2:$G$4220,MATCH(A10,'Watch Paths'!$N$2:$N$4220,0)),"✓ complete") -> Workers Leaving the Lumière Factory | I10: Film as spectacle before storytelling took over, then the first grammar of narrative. | J10: Thompson & Bordwell, Film History: An Introduction; Cousins, The Story of Film (book 2004 / series 2011); Gunning, 'The Cinema of Attractions' (1986)
A11: N010 | B11: 02 Film History Spine (chronological) | C11: 1. Silent Era (1895–1929) | D11: American silent features & Griffith | E11: =COUNTIF('Watch Paths'!$A$2:$A$4220,A11) -> 10 | F11: =COUNTIFS('Watch Paths'!$A$2:$A$4220,A11,'Watch Paths'!$M$2:$M$4220,1) -> 0 | G11: =IF(E11=0,0,F11/E11) -> 0 | H11: =IFERROR(INDEX('Watch Paths'!$G$2:$G$4220,MATCH(A11,'Watch Paths'!$N$2:$N$4220,0)),"✓ complete") -> The Birth of a Nation | I11: Feature-length storytelling, the star system, and the film-grammar consolidation (and racism) of Griffith. | J11: Thompson & Bordwell, Film History: An Introduction; Cousins, The Story of Film (book 2004 / series 2011); Brownlow, The Parade's Gone By… (1968)
A12: N011 | B12: 02 Film History Spine (chronological) | C12: 1. Silent Era (1895–1929) | D12: Silent comedy: Chaplin, Keaton, Lloyd | E12: =COUNTIF('Watch Paths'!$A$2:$A$4220,A12) -> 11 | F12: =COUNTIFS('Watch Paths'!$A$2:$A$4220,A12,'Watch Paths'!$M$2:$M$4220,1) -> 1 | G12: =IF(E12=0,0,F12/E12) -> 0.090909091 | H12: =IFERROR(INDEX('Watch Paths'!$G$2:$G$4220,MATCH(A12,'Watch Paths'!$N$2:$N$4220,0)),"✓ complete") -> Sherlock Jr. | I12: The purest visual storytelling ever put on screen. Start with Keaton. | J12: Thompson & Bordwell, Film History: An Introduction; Cousins, The Story of Film (book 2004 / series 2011); Agee, 'Comedy's Greatest Era' (Life, 1949); Kerr, The Silent Clowns (1975)
A13: N012 | B13: 02 Film History Spine (chronological) | C13: 1. Silent Era (1895–1929) | D13: German Expressionism & Weimar cinema | E13: =COUNTIF('Watch Paths'!$A$2:$A$4220,A13) -> 12 | F13: =COUNTIFS('Watch Paths'!$A$2:$A$4220,A13,'Watch Paths'!$M$2:$M$4220,1) -> 1 | G13: =IF(E13=0,0,F13/E13) -> 0.083333333 | H13: =IFERROR(INDEX('Watch Paths'!$G$2:$G$4220,MATCH(A13,'Watch Paths'!$N$2:$N$4220,0)),"✓ complete") -> The Cabinet of Dr. Caligari | I13: Distorted sets, shadows, and the psyche of a nation between wars. Also the root of horror and noir. | J13: Thompson & Bordwell, Film History: An Introduction; Cousins, The Story of Film (book 2004 / series 2011); Eisner, The Haunted Screen (1952); Kracauer, From Caligari to Hitler (1947)
... A331: N330 | B331: 10 Bridges From Your 5-Star Films | C331: Genre Lines From Your Favorites | D331: Because you loved Everything Everywhere All at Once & Barbie | E331: =COUNTIF('Watch Paths'!$A$2:$A$4220,A331) -> 11 | F331: =COUNTIFS('Watch Paths'!$A$2:$A$4220,A331,'Watch Paths'!$M$2:$M$4220,1) -> 2 | G331: =IF(E331=0,0,F331/E331) -> 0.18181818 | H331: =IFERROR(INDEX('Watch Paths'!$G$2:$G$4220,MATCH(A331,'Watch Paths'!$N$2:$N$4220,0)),"✓ complete") -> The Holy Mountain | I331: Maximalist, genre-smashing, heartfelt pop films. | J331: Built from your Letterboxd ratings (5-star films) and the influence lines in this guide

Sheet Master List
A1: Title | B1: Year | C1: Decade | D1: Director | E1: Seen | F1: Buckets | G1: Seen # | H1: Centrality Score | I1: Best Tier | J1: Primary Category | K1: All Niches | L1: Letterboxd | M1: Match Key | N1: In Cat 01 | O1: In Cat 02 | P1: In Cat 03 | Q1: In Cat 04 | R1: In Cat 05 | S1: In Cat 06 | T1: In Cat 07 | U1: In Cat 08 | V1: In Cat 09 | W1: In Cat 10
A2: 10 Rillington Place | B2: 1971 | C2: =FLOOR(B2,10)&"s" -> 1970s | D2: Richard Fleischer | E2: =IF(G2=1,"✓","") | F2: 1 | G2: =IF(COUNTIF('Letterboxd Watched'!$E$2:$E$3000,M2)>0,1,0) -> 0 | H2: 1 | I2: 3 · Deep Cut | J2: 04 Genres & Subgenres | K2: Serial killer procedurals | L2: =HYPERLINK("https://boxd.it/1uig","open") -> open | M2: =LOWER(A2)&"|"&B2 -> 10 rillington place|1971 | N2: 0 | O2: 0 | P2: 0 | Q2: 1 | R2: 0 | S2: 0 | T2: 0 | U2: 0 | V2: 0 | W2: 0
A3: 12:08 East of Bucharest | B3: 2006 | C3: =FLOOR(B3,10)&"s" -> 2000s | D3: Corneliu Porumboiu | E3: =IF(G3=1,"✓","") | F3: 1 | G3: =IF(COUNTIF('Letterboxd Watched'!$E$2:$E$3000,M3)>0,1,0) -> 0 | H3: 2 | I3: 2 · Core | J3: 03 World Cinemas & Movements | K3: Romanian New Wave | L3: =HYPERLINK("https://letterboxd.com/search/films/1208+East+of+Bucharest+2006/","open") -> open | M3: =LOWER(A3)&"|"&B3 -> 12:08 east of bucharest|2006 | N3: 0 | O3: 0 | P3: 1 | Q3: 0 | R3: 0 | S3: 0 | T3: 0 | U3: 0 | V3: 0 | W3: 0
A4: 12 Angry Men | B4: 1957 | C4: =FLOOR(B4,10)&"s" -> 1950s | D4: Sidney Lumet | E4: =IF(G4=1,"✓","") -> ✓ | F4: 5 | G4: =IF(COUNTIF('Letterboxd Watched'!$E$2:$E$3000,M4)>0,1,0) -> 1 | H4: 13 | I4: 1 · Start Here | J4: 05 Auteurs & Filmographies | K4: Sidney Lumet; Law, courts & justice; Real-time films; Single-location & chamber films; AFI 100 Years...100 Movies (2007 ed.) — selections | L4: =HYPERLINK("https://boxd.it/2auI","open") -> open | M4: =LOWER(A4)&"|"&B4 -> 12 angry men|1957 | N4: 0 | O4: 0 | P4: 0 | Q4: 0 | R4: 1 | S4: 0 | T4: 1 | U4: 1 | V4: 1 | W4: 0
A5: 12 Monkeys | B5: 1995 | C5: =FLOOR(B5,10)&"s" -> 1990s | D5: Terry Gilliam | E5: =IF(G5=1,"✓","") | F5: 1 | G5: =IF(COUNTIF('Letterboxd Watched'!$E$2:$E$3000,M5)>0,1,0) -> 0 | H5: 2 | I5: 2 · Core | J5: 07 Themes & Subjects | K5: Time, memory & loops | L5: =HYPERLINK("https://letterboxd.com/search/films/12+Monkeys+1995/","open") -> open | M5: =LOWER(A5)&"|"&B5 -> 12 monkeys|1995 | N5: 0 | O5: 0 | P5: 0 | Q5: 0 | R5: 0 | S5: 0 | T5: 1 | U5: 0 | V5: 0 | W5: 0
A6: 12 Years a Slave | B6: 2013 | C6: =FLOOR(B6,10)&"s" -> 2010s | D6: Steve McQueen | E6: =IF(G6=1,"✓","") | F6: 1 | G6: =IF(COUNTIF('Letterboxd Watched'!$E$2:$E$3000,M6)>0,1,0) -> 0 | H6: 2 | I6: 2 · Core | J6: 07 Themes & Subjects | K6: American history on film | L6: =HYPERLINK("https://boxd.it/2D2e","open") -> open | M6: =LOWER(A6)&"|"&B6 -> 12 years a slave|2013 | N6: 0 | O6: 0 | P6: 0 | Q6: 0 | R6: 0 | S6: 0 | T6: 1 | U6: 0 | V6: 0 | W6: 0
A7: 127 Hours | B7: 2010 | C7: =FLOOR(B7,10)&"s" -> 2010s | D7: Danny Boyle | E7: =IF(G7=1,"✓","") | F7: 1 | G7: =IF(COUNTIF('Letterboxd Watched'!$E$2:$E$3000,M7)>0,1,0) -> 0 | H7: 2 | I7: 2 · Core | J7: 04 Genres & Subgenres | K7: Survival & man-vs-nature | L7: =HYPERLINK("https://boxd.it/SLa","open") -> open | M7: =LOWER(A7)&"|"&B7 -> 127 hours|2010 | N7: 0 | O7: 0 | P7: 0 | Q7: 1 | R7: 0 | S7: 0 | T7: 0 | U7: 0 | V7: 0 | W7: 0
A8: 13 Assassins | B8: 2010 | C8: =FLOOR(B8,10)&"s" -> 2010s | D8: Takashi Miike | E8: =IF(G8=1,"✓","") | F8: 1 | G8: =IF(COUNTIF('Letterboxd Watched'!$E$2:$E$3000,M8)>0,1,0) -> 0 | H8: 2 | I8: 2 · Core | J8: 03 World Cinemas & Movements | K8: Samurai: jidaigeki & chanbara | L8: =HYPERLINK("https://boxd.it/jqc","open") -> open | M8: =LOWER(A8)&"|"&B8 -> 13 assassins|2010 | N8: 0 | O8: 0 | P8: 1 | Q8: 0 | R8: 0 | S8: 0 | T8: 0 | U8: 0 | V8: 0 | W8: 0
A9: 13th | B9: 2016 | C9: =FLOOR(B9,10)&"s" -> 2010s | D9: Ava DuVernay | E9: =IF(G9=1,"✓","") | F9: 1 | G9: =IF(COUNTIF('Letterboxd Watched'!$E$2:$E$3000,M9)>0,1,0) -> 0 | H9: 2 | I9: 2 · Core | J9: 06 Theory & Academic Lenses | K9: Black American cinema: 1986 to now | L9: =HYPERLINK("https://boxd.it/elNg","open") -> open | M9: =LOWER(A9)&"|"&B9 -> 13th|2016 | N9: 0 | O9: 0 | P9: 0 | Q9: 0 | R9: 0 | S9: 1 | T9: 0 | U9: 0 | V9: 0 | W9: 0
A10: 1917 | B10: 2019 | C10: =FLOOR(B10,10)&"s" -> 2010s | D10: Sam Mendes | E10: =IF(G10=1,"✓","") -> ✓ | F10: 2 | G10: =IF(COUNTIF('Letterboxd Watched'!$E$2:$E$3000,M10)>0,1,0) -> 1 | H10: 4 | I10: 2 · Core | J10: 01 Foundations: Learning to Watch | K10: The long take & the oner; World War I | L10: =HYPERLINK("https://boxd.it/jj4y","open") -> open | M10: =LOWER(A10)&"|"&B10 -> 1917|2019 | N10: 1 | O10: 0 | P10: 0 | Q10: 1 | R10: 0 | S10: 0 | T10: 0 | U10: 0 | V10: 0 | W10: 0
A11: 1941 | B11: 1979 | C11: =FLOOR(B11,10)&"s" -> 1970s | D11: Steven Spielberg | E11: =IF(G11=1,"✓","") -> ✓ | F11: 1 | G11: =IF(COUNTIF('Letterboxd Watched'!$E$2:$E$3000,M11)>0,1,0) -> 1 | H11: 1 | I11: 3 · Deep Cut | J11: 05 Auteurs & Filmographies | K11: Steven Spielberg | L11: =HYPERLINK("https://boxd.it/1TF0","open") -> open | M11: =LOWER(A11)&"|"&B11 -> 1941|1979 | N11: 0 | O11: 0 | P11: 0 | Q11: 0 | R11: 1 | S11: 0 | T11: 0 | U11: 0 | V11: 0 | W11: 0
A12: 2 or 3 Things I Know About Her | B12: 1967 | C12: =FLOOR(B12,10)&"s" -> 1960s | D12: Jean-Luc Godard | E12: =IF(G12=1,"✓","") | F12: 1 | G12: =IF(COUNTIF('Letterboxd Watched'!$E$2:$E$3000,M12)>0,1,0) -> 0 | H12: 2 | I12: 2 · Core | J12: 05 Auteurs & Filmographies | K12: Jean-Luc Godard | L12: =HYPERLINK("https://boxd.it/20Am","open") -> open | M12: =LOWER(A12)&"|"&B12 -> 2 or 3 things i know about her|1967 | N12: 0 | O12: 0 | P12: 0 | Q12: 0 | R12: 1 | S12: 0 | T12: 0 | U12: 0 | V12: 0 | W12: 0
A13: 2001: A Space Odyssey | B13: 1968 | C13: =FLOOR(B13,10)&"s" -> 1960s | D13: Stanley Kubrick | E13: =IF(G13=1,"✓","") -> ✓ | F13: 7 | G13: =IF(COUNTIF('Letterboxd Watched'!$E$2:$E$3000,M13)>0,1,0) -> 1 | H13: 16 | I13: 1 · Start Here | J13: 02 Film History Spine (chronological) | K13: The movie-brat revolution; 1960s–70s New Wave sci-fi; Stanley Kubrick; AI, computers & the internet; Sight & Sound 2022 Critics' Poll — selections (unranked); AFI 100 Years...100 Movies (2007 ed.) — selections; Because you loved First Reformed & The Tree of Life | L13: =HYPERLINK("https://boxd.it/2bf0","open") -> open | M13: =LOWER(A13)&"|"&B13 -> 2001: a space odyssey|1968 | N13: 0 | O13: 1 | P13: 0 | Q13: 1 | R13: 1 | S13: 0 | T13: 1 | U13: 0 | V13: 1 | W13: 1
A14: 2046 | B14: 2004 | C14: =FLOOR(B14,10)&"s" -> 2000s | D14: Wong Kar-wai | E14: =IF(G14=1,"✓","") -> ✓ | F14: 1 | G14: =IF(COUNTIF('Letterboxd Watched'!$E$2:$E$3000,M14)>0,1,0) -> 1 | H14: 2 | I14: 2 · Core | J14: 05 Auteurs & Filmographies | K14: Wong Kar-wai | L14: =HYPERLINK("https://boxd.it/29tu","open") -> open | M14: =LOWER(A14)&"|"&B14 -> 2046|2004 | N14: 0 | O14: 0 | P14: 0 | Q14: 0 | R14: 1 | S14: 0 | T14: 0 | U14: 0 | V14: 0 | W14: 0
A15: 24 Frames | B15: 2017 | C15: =FLOOR(B15,10)&"s" -> 2010s | D15: Abbas Kiarostami | E15: =IF(G15=1,"✓","") | F15: 1 | G15: =IF(COUNTIF('Letterboxd Watched'!$E$2:$E$3000,M15)>0,1,0) -> 0 | H15: 1 | I15: 3 · Deep Cut | J15: 05 Auteurs & Filmographies | K15: Abbas Kiarostami | L15: =HYPERLINK("https://letterboxd.com/search/films/24+Frames+2017/","open") -> open | M15: =LOWER(A15)&"|"&B15 -> 24 frames|2017 | N15: 0 | O15: 0 | P15: 0 | Q15: 0 | R15: 1 | S15: 0 | T15: 0 | U15: 0 | V15: 0 | W15: 0
A16: 24 Hour Party People | B16: 2002 | C16: =FLOOR(B16,10)&"s" -> 2000s | D16: Michael Winterbottom | E16: =IF(G16=1,"✓","") | F16: 1 | G16: =IF(COUNTIF('Letterboxd Watched'!$E$2:$E$3000,M16)>0,1,0) -> 0 | H16: 2 | I16: 2 · Core | J16: 07 Themes & Subjects | K16: Music & musicians | L16: =HYPERLINK("https://boxd.it/26nI","open") -> open | M16: =LOWER(A16)&"|"&B16 -> 24 hour party people|2002 | N16: 0 | O16: 0 | P16: 0 | Q16: 0 | R16: 0 | S16: 0 | T16: 1 | U16: 0 | V16: 0 | W16: 0
A17: 25th Hour | B17: 2002 | C17: =FLOOR(B17,10)&"s" -> 2000s | D17: Spike Lee | E17: =IF(G17=1,"✓","") | F17: 1 | G17: =IF(COUNTIF('Letterboxd Watched'!$E$2:$E$3000,M17)>0,1,0) -> 0 | H17: 2 | I17: 2 · Core | J17: 05 Auteurs & Filmographies | K17: Spike Lee | L17: =HYPERLINK("https://boxd.it/28LC","open") -> open | M17: =LOWER(A17)&"|"&B17 -> 25th hour|2002 | N17: 0 | O17: 0 | P17: 0 | Q17: 0 | R17: 1 | S17: 0 | T17: 0 | U17: 0 | V17: 0 | W17: 0
A18: 28 Days Later | B18: 2002 | C18: =FLOOR(B18,10)&"s" -> 2000s | D18: Danny Boyle | E18: =IF(G18=1,"✓","") | F18: 2 | G18: =IF(COUNTIF('Letterboxd Watched'!$E$2:$E$3000,M18)>0,1,0) -> 0 | H18: 4 | I18: 2 · Core | J18: 04 Genres & Subgenres | K18: Zombie lineage; Because you loved The Thing, Children of Men & War of the Worlds | L18: =HYPERLINK("https://boxd.it/2aXU","open") -> open | M18: =LOWER(A18)&"|"&B18 -> 28 days later|2002 | N18: 0 | O18: 0 | P18: 0 | Q18: 1 | R18: 0 | S18: 0 | T18: 0 | U18: 0 | V18: 0 | W18: 1
A19: 3:10 to Yuma | B19: 1957 | C19: =FLOOR(B19,10)&"s" -> 1950s | D19: Delmer Daves | E19: =IF(G19=1,"✓","") | F19: 1 | G19: =IF(COUNTIF('Letterboxd Watched'!$E$2:$E$3000,M19)>0,1,0) -> 0 | H19: 2 | I19: 2 · Core | J19: 04 Genres & Subgenres | K19: Ranown cycle & the adult western | L19: =HYPERLINK("https://boxd.it/1OCU","open") -> open | M19: =LOWER(A19)&"|"&B19 -> 3:10 to yuma|1957 | N19: 0 | O19: 0 | P19: 0 | Q19: 1 | R19: 0 | S19: 0 | T19: 0 | U19: 0 | V19: 0 | W19: 0
A20: 3 Women | B20: 1977 | C20: =FLOOR(B20,10)&"s" -> 1970s | D20: Robert Altman | E20: =IF(G20=1,"✓","") | F20: 1 | G20: =IF(COUNTIF('Letterboxd Watched'!$E$2:$E$3000,M20)>0,1,0) -> 0 | H20: 2 | I20: 2 · Core | J20: 05 Auteurs & Filmographies | K20: Robert Altman | L20: =HYPERLINK("https://boxd.it/YPs","open") -> open | M20: =LOWER(A20)&"|"&B20 -> 3 women|1977 | N20: 0 | O20: 0 | P20: 0 | Q20: 0 | R20: 1 | S20: 0 | T20: 0 | U20: 0 | V20: 0 | W20: 0
A21: 35 Shots of Rum | B21: 2008 | C21: =FLOOR(B21,10)&"s" -> 2000s | D21: Claire Denis | E21: =IF(G21=1,"✓","") | F21: 1 | G21: =IF(COUNTIF('Letterboxd Watched'!$E$2:$E$3000,M21)>0,1,0) -> 0 | H21: 3 | I21: 1 · Start Here | J21: 05 Auteurs & Filmographies | K21: Claire Denis | L21: =HYPERLINK("https://boxd.it/1unA","open") -> open | M21: =LOWER(A21)&"|"&B21 -> 35 shots of rum|2008 | N21: 0 | O21: 0 | P21: 0 | Q21: 0 | R21: 1 | S21: 0 | T21: 0 | U21: 0 | V21: 0 | W21: 0
A22: The 36th Chamber of Shaolin | B22: 1978 | C22: =FLOOR(B22,10)&"s" -> 1970s | D22: Lau Kar-leung | E22: =IF(G22=1,"✓","") | F22: 1 | G22: =IF(COUNTIF('Letterboxd Watched'!$E$2:$E$3000,M22)>0,1,0) -> 0 | H22: 2 | I22: 2 · Core | J22: 03 World Cinemas & Movements | K22: Hong Kong action: Shaw Bros to heroic bloodshed | L22: =HYPERLINK("https://boxd.it/1SXC","open") -> open | M22: =LOWER(A22)&"|"&B22 -> the 36th chamber of shaolin|1978 | N22: 0 | O22: 0 | P22: 1 | Q22: 0 | R22: 0 | S22: 0 | T22: 0 | U22: 0 | V22: 0 | W22: 0
A23: The 39 Steps | B23: 1935 | C23: =FLOOR(B23,10)&"s" -> 1930s | D23: Alfred Hitchcock | E23: =IF(G23=1,"✓","") | F23: 3 | G23: =IF(COUNTIF('Letterboxd Watched'!$E$2:$E$3000,M23)>0,1,0) -> 0 | H23: 6 | I23: 2 · Core | J23: 04 Genres & Subgenres | K23: Espionage & Cold War spy; Alfred Hitchcock; BFI 100 Best British Films (1999) — selections | L23: =HYPERLINK("https://boxd.it/2aKc","open") -> open | M23: =LOWER(A23)&"|"&B23 -> the 39 steps|1935 | N23: 0 | O23: 0 | P23: 0 | Q23: 1 | R23: 1 | S23: 0 | T23: 0 | U23: 0 | V23: 1 | W23: 0
A24: 4 Little Girls | B24: 1997 | C24: =FLOOR(B24,10)&"s" -> 1990s | D24: Spike Lee | E24: =IF(G24=1,"✓","") | F24: 1 | G24: =IF(COUNTIF('Letterboxd Watched'!$E$2:$E$3000,M24)>0,1,0) -> 0 | H24: 2 | I24: 2 · Core | J24: 05 Auteurs & Filmographies | K24: Spike Lee | L24: =HYPERLINK("https://boxd.it/1tAS","open") -> open | M24: =LOWER(A24)&"|"&B24 -> 4 little girls|1997 | N24: 0 | O24: 0 | P24: 0 | Q24: 0 | R24: 1 | S24: 0 | T24: 0 | U24: 0 | V24: 0 | W24: 0
A25: 4 Months, 3 Weeks and 2 Days | B25: 2007 | C25: =FLOOR(B25,10)&"s" -> 2000s | D25: Cristian Mungiu | E25: =IF(G25=1,"✓","") | F25: 1 | G25: =IF(COUNTIF('Letterboxd Watched'!$E$2:$E$3000,M25)>0,1,0) -> 0 | H25: 3 | I25: 1 · Start Here | J25: 03 World Cinemas & Movements | K25: Romanian New Wave | L25: =HYPERLINK("https://boxd.it/27DW","open") -> open | M25: =LOWER(A25)&"|"&B25 -> 4 months, 3 weeks and 2 days|2007 | N25: 0 | O25: 0 | P25: 1 | Q25: 0 | R25: 0 | S25: 0 | T25: 0 | U25: 0 | V25: 0 | W25: 0
A26: The 400 Blows | B26: 1959 | C26: =FLOOR(B26,10)&"s" -> 1950s | D26: François Truffaut | E26: =IF(G26=1,"✓","") | F26: 8 | G26: =IF(COUNTIF('Letterboxd Watched'!$E$2:$E$3000,M26)>0,1,0) -> 0 | H26: 22 | I26: 1 · Start Here | J26: 02 Film History Spine (chronological) | K26: The global new-wave explosion; French New Wave (Nouvelle Vague); François Truffaut & Éric Rohmer; Coming of age; Paris & Tokyo; Films shot over years; Film debuts that announced a master; The Criterion Collection — art-house starter pack | L26: =HYPERLINK("https://boxd.it/2b1C","open") -> open | M26: =LOWER(A26)&"|"&B26 -> the 400 blows|1959 | N26: 0 | O26: 1 | P26: 1 | Q26: 0 | R26: 1 | S26: 0 | T26: 1 | U26: 1 | V26: 1 | W26: 0
A27: 42nd Street | B27: 1933 | C27: =FLOOR(B27,10)&"s" -> 1930s | D27: Lloyd Bacon | E27: =IF(G27=1,"✓","") | F27: 1 | G27: =IF(COUNTIF('Letterboxd Watched'!$E$2:$E$3000,M27)>0,1,0) -> 0 | H27: 2 | I27: 2 · Core | J27: 04 Genres & Subgenres | K27: Classic Hollywood musical: Berkeley, Astaire, Freed Unit | L27: =HYPERLINK("https://boxd.it/25PQ","open") -> open | M27: =LOWER(A27)&"|"&B27 -> 42nd street|1933 | N27: 0 | O27: 0 | P27: 0 | Q27: 1 | R27: 0 | S27: 0 | T27: 0 | U27: 0 | V27: 0 | W27: 0
A28: 49 Up | B28: 2005 | C28: =FLOOR(B28,10)&"s" -> 2000s | D28: Michael Apted | E28: =IF(G28=1,"✓","") | F28: 1 | G28: =IF(COUNTIF('Letterboxd Watched'!$E$2:$E$3000,M28)>0,1,0) -> 0 | H28: 1 | I28: 3 · Deep Cut | J28: 08 Niches & Micro-genres | K28: Films shot over years | L28: =HYPERLINK("https://letterboxd.com/search/films/49+Up+2005/","open") -> open | M28: =LOWER(A28)&"|"&B28 -> 49 up|2005 | N28: 0 | O28: 0 | P28: 0 | Q28: 0 | R28: 0 | S28: 0 | T28: 0 | U28: 1 | V28: 0 | W28: 0
A29: 49th Parallel | B29: 1941 | C29: =FLOOR(B29,10)&"s" -> 1940s | D29: Michael Powell | E29: =IF(G29=1,"✓","") | F29: 1 | G29: =IF(COUNTIF('Letterboxd Watched'!$E$2:$E$3000,M29)>0,1,0) -> 0 | H29: 1 | I29: 3 · Deep Cut | J29: 03 World Cinemas & Movements | K29: Powell & Pressburger (The Archers) | L29: =HYPERLINK("https://letterboxd.com/search/films/49th+Parallel+1941/","open") -> open | M29: =LOWER(A29)&"|"&B29 -> 49th parallel|1941 | N29: 0 | O29: 0 | P29: 1 | Q29: 0 | R29: 0 | S29: 0 | T29: 0 | U29: 0 | V29: 0 | W29: 0
A30: 63 Up | B30: 2019 | C30: =FLOOR(B30,10)&"s" -> 2010s | D30: Michael Apted | E30: =IF(G30=1,"✓","") | F30: 1 | G30: =IF(COUNTIF('Letterboxd Watched'!$E$2:$E$3000,M30)>0,1,0) -> 0 | H30: 1 | I30: 3 · Deep Cut | J30: 08 Niches & Micro-genres | K30: Films shot over years | L30: =HYPERLINK("https://letterboxd.com/search/films/63+Up+2019/","open") -> open | M30: =LOWER(A30)&"|"&B30 -> 63 up|2019 | N30: 0 | O30: 0 | P30: 0 | Q30: 0 | R30: 0 | S30: 0 | T30: 0 | U30: 1 | V30: 0 | W30: 0
A31: 71 Fragments of a Chronology of Chance | B31: 1994 | C31: =FLOOR(B31,10)&"s" -> 1990s | D31: Michael Haneke | E31: =IF(G31=1,"✓","") | F31: 2 | G31: =IF(COUNTIF('Letterboxd Watched'!$E$2:$E$3000,M31)>0,1,0) -> 0 | H31: 3 | I31: 2 · Core | J31: 05 Auteurs & Filmographies | K31: Michael Haneke; Hyperlink & network narrative | L31: =HYPERLINK("https://boxd.it/1gAU","open") -> open | M31: =LOWER(A31)&"|"&B31 -> 71 fragments of a chronology of chance|1994 | N31: 0 | O31: 0 | P31: 0 | Q31: 0 | R31: 1 | S31: 1 | T31: 0 | U31: 0 | V31: 0 | W31: 0
A32: 8 Women | B32: 2002 | C32: =FLOOR(B32,10)&"s" -> 2000s | D32: François Ozon | E32: =IF(G32=1,"✓","") | F32: 1 | G32: =IF(COUNTIF('Letterboxd Watched'!$E$2:$E$3000,M32)>0,1,0) -> 0 | H32: 2 | I32: 2 · Core | J32: 04 Genres & Subgenres | K32: Jacques Demy & the European musical | L32: =HYPERLINK("https://letterboxd.com/search/films/8+Women+2002/","open") -> open | M32: =LOWER(A32)&"|"&B32 -> 8 women|2002 | N32: 0 | O32: 0 | P32: 0 | Q32: 1 | R32: 0 | S32: 0 | T32: 0 | U32: 0 | V32: 0 | W32: 0
A33: 8½ | B33: 1963 | C33: =FLOOR(B33,10)&"s" -> 1960s | D33: Federico Fellini | E33: =IF(G33=1,"✓","") | F33: 7 | G33: =IF(COUNTIF('Letterboxd Watched'!$E$2:$E$3000,M33)>0,1,0) -> 0 | H33: 17 | I33: 1 · Start Here | J33: 02 Film History Spine (chronological) | K33: The global new-wave explosion; Italian modernism: Fellini, Antonioni, Visconti, Pasolini; Federico Fellini; Deleuze: movement-image to time-image; Movies about movies; Sight & Sound 2022 Critics' Poll — selections (unranked); Because you loved Synecdoche, NY & I'm Thinking of Ending Things | L33: =HYPERLINK("https://boxd.it/2aqm","open") -> open | M33: =LOWER(A33)&"|"&B33 -> 8½|1963 | N33: 0 | O33: 1 | P33: 1 | Q33: 0 | R33: 1 | S33: 1 | T33: 1 | U33: 0 | V33: 1 | W33: 1
A34: L.A. Confidential | B34: 1997 | C34: =FLOOR(B34,10)&"s" -> 1990s | D34: Curtis Hanson | E34: =IF(G34=1,"✓","") | F34: 1 | G34: =IF(COUNTIF('Letterboxd Watched'!$E$2:$E$3000,M34)>0,1,0) -> 0 | H34: 3 | I34: 1 · Start Here | J34: 04 Genres & Subgenres | K34: Neo-noir | L34: =HYPERLINK("https://boxd.it/27oC","open") -> open | M34: =LOWER(A34)&"|"&B34 -> l.a. confidential|1997 | N34: 0 | O34: 0 | P34: 0 | Q34: 1 | R34: 0 | S34: 0 | T34: 0 | U34: 0 | V34: 0 | W34: 0
A35: About Schmidt | B35: 2002 | C35: =FLOOR(B35,10)&"s" -> 2000s | D35: Alexander Payne | E35: =IF(G35=1,"✓","") | F35: 1 | G35: =IF(COUNTIF('Letterboxd Watched'!$E$2:$E$3000,M35)>0,1,0) -> 0 | H35: 2 | I35: 2 · Core | J35: 07 Themes & Subjects | K35: Aging, mortality & grief | L35: =HYPERLINK("https://boxd.it/26mU","open") -> open | M35: =LOWER(A35)&"|"&B35 -> about schmidt|2002 | N35: 0 | O35: 0 | P35: 0 | Q35: 0 | R35: 0 | S35: 0 | T35: 1 | U35: 0 | V35: 0 | W35: 0
A36: Abre los Ojos | B36: 1997 | C36: =FLOOR(B36,10)&"s" -> 1990s | D36: Alejandro Amenábar | E36: =IF(G36=1,"✓","") | F36: 2 | G36: =IF(COUNTIF('Letterboxd Watched'!$E$2:$E$3000,M36)>0,1,0) -> 0 | H36: 2 | I36: 3 · Deep Cut | J36: 06 Theory & Academic Lenses | K36: Mind-game & puzzle films; East–West remakes & lineages | L36: =HYPERLINK("https://letterboxd.com/search/films/Abre+los+Ojos+1997/","open") -> open | M36: =LOWER(A36)&"|"&B36 -> abre los ojos|1997 | N36: 0 | O36: 0 | P36: 0 | Q36: 0 | R36: 0 | S36: 1 | T36: 0 | U36: 1 | V36: 0 | W36: 0
A37: Absence of Malice | B37: 1981 | C37: =FLOOR(B37,10)&"s" -> 1980s | D37: Sydney Pollack | E37: =IF(G37=1,"✓","") | F37: 1 | G37: =IF(COUNTIF('Letterboxd Watched'!$E$2:$E$3000,M37)>0,1,0) -> 0 | H37: 1 | I37: 3 · Deep Cut | J37: 07 Themes & Subjects | K37: Journalism & the press | L37: =HYPERLINK("https://boxd.it/1F74","open") -> open | M37: =LOWER(A37)&"|"&B37 -> absence of malice|1981 | N37: 0 | O37: 0 | P37: 0 | Q37: 0 | R37: 0 | S37: 0 | T37: 1 | U37: 0 | V37: 0 | W37: 0
A38: Accattone | B38: 1961 | C38: =FLOOR(B38,10)&"s" -> 1960s | D38: Pier Paolo Pasolini | E38: =IF(G38=1,"✓","") | F38: 1 | G38: =IF(COUNTIF('Letterboxd Watched'!$E$2:$E$3000,M38)>0,1,0) -> 0 | H38: 2 | I38: 2 · Core | J38: 03 World Cinemas & Movements | K38: Italian modernism: Fellini, Antonioni, Visconti, Pasolini | L38: =HYPERLINK("https://letterboxd.com/search/films/Accattone+1961/","open") -> open | M38: =LOWER(A38)&"|"&B38 -> accattone|1961 | N38: 0 | O38: 0 | P38: 1 | Q38: 0 | R38: 0 | S38: 0 | T38: 0 | U38: 0 | V38: 0 | W38: 0
A39: Ace in the Hole | B39: 1951 | C39: =FLOOR(B39,10)&"s" -> 1950s | D39: Billy Wilder | E39: =IF(G39=1,"✓","") | F39: 3 | G39: =IF(COUNTIF('Letterboxd Watched'!$E$2:$E$3000,M39)>0,1,0) -> 0 | H39: 6 | I39: 2 · Core | J39: 04 Genres & Subgenres | K39: Classic noir (1941–1958); Billy Wilder; Journalism & the press | L39: =HYPERLINK("https://boxd.it/1vXk","open") -> open | M39: =LOWER(A39)&"|"&B39 -> ace in the hole|1951 | N39: 0 | O39: 0 | P39: 0 | Q39: 1 | R39: 1 | S39: 0 | T39: 1 | U39: 0 | V39: 0 | W39: 0
A40: Across 110th Street | B40: 1972 | C40: =FLOOR(B40,10)&"s" -> 1970s | D40: Barry Shear | E40: =IF(G40=1,"✓","") | F40: 1 | G40: =IF(COUNTIF('Letterboxd Watched'!$E$2:$E$3000,M40)>0,1,0) -> 0 | H40: 2 | I40: 2 · Core | J40: 06 Theory & Academic Lenses | K40: Blaxploitation & its reckoning | L40: =HYPERLINK("https://boxd.it/1yHO","open") -> open | M40: =LOWER(A40)&"|"&B40 -> across 110th street|1972 | N40: 0 | O40: 0 | P40: 0 | Q40: 0 | R40: 0 | S40: 1 | T40: 0 | U40: 0 | V40: 0 | W40: 0
...

Sheet Bibliography
A1: Source | B1: Used for (niches) | C1: # Niches
A2: 'Neo-neorealism' (Scott, NYT 2009) | B2: Kelly Reichardt & the new American regionalists | C2: 1
A3: A24 catalog | B3: A24 — the indie-studio era | C3: 1
A4: ABA 'Top 25 Legal Movies' (2008) | B4: Law, courts & justice | C4: 1
A5: Abbas, Hong Kong: Culture and the Politics of Disappearance (1997) | B5: Hong Kong New Wave & second wave | C5: 1
A6: Abel, French Cinema: The First Wave, 1915–1929 (1984) | B6: French Impressionism & the avant-garde | C6: 1
A7: Abel, The Counter-Cinema of the Berlin School (2013) | B7: Berlin School & contemporary German-language cinema | C7: 1
A8: Agee, 'Comedy's Greatest Era' (Life, 1949) | B8: Silent comedy: Chaplin, Keaton, Lloyd | C8: 1
A9: Altman | B9: Roadshow, rock & revisionist musicals | C9: 1
A10: Altman, The American Film Musical (1987) | B10: Classic Hollywood musical: Berkeley, Astaire, Freed Unit | C10: 1
A11: American Film Institute, AFI's 100 Years...100 Movies — 10th Anniversary Edition (2007) | B11: AFI 100 Years...100 Movies (2007 ed.) — selections | C11: 1
A12: American Grindhouse (doc, 2010) | B12: Exploitation & grindhouse history | C12: 1
A13: Ames, Movies About the Movies: Hollywood Reflected (1997) | B13: Movies about movies | C13: 1
... A539: Zuckoff, Robert Altman: The Oral Biography (2009) | B539: Robert Altman | C539: 1

Sheet Letterboxd Watched
A1: Date | B1: Name | C1: Year | D1: Letterboxd URI | E1: Match Key (formula)
A2: 2020-12-30 | B2: Parasite | C2: 2019 | D2: https://boxd.it/hTha | E2: =IF(B2="","",LOWER(B2)&"|"&C2) -> parasite|2019
A3: 2020-12-30 | B3: Joker | C3: 2019 | D3: https://boxd.it/h4cS | E3: =IF(B3="","",LOWER(B3)&"|"&C3) -> joker|2019
A4: 2020-12-30 | B4: Knives Out | C4: 2019 | D4: https://boxd.it/jWEA | E4: =IF(B4="","",LOWER(B4)&"|"&C4) -> knives out|2019
A5: 2020-12-30 | B5: Get Out | C5: 2017 | D5: https://boxd.it/eOCm | E5: =IF(B5="","",LOWER(B5)&"|"&C5) -> get out|2017
A6: 2020-12-30 | B6: Inception | C6: 2010 | D6: https://boxd.it/1skk | E6: =IF(B6="","",LOWER(B6)&"|"&C6) -> inception|2010
A7: 2020-12-30 | B7: Fight Club | C7: 1999 | D7: https://boxd.it/2a9q | E7: =IF(B7="","",LOWER(B7)&"|"&C7) -> fight club|1999
A8: 2020-12-30 | B8: The Shining | C8: 1980 | D8: https://boxd.it/29Nu | E8: =IF(B8="","",LOWER(B8)&"|"&C8) -> the shining|1980
A9: 2020-12-30 | B9: Eternal Sunshine of the Spotless Mind | C9: 2004 | D9: https://boxd.it/6YK | E9: =IF(B9="","",LOWER(B9)&"|"&C9) -> eternal sunshine of the spotless mind|2004
A10: 2020-12-30 | B10: The Truman Show | C10: 1998 | D10: https://boxd.it/18U8 | E10: =IF(B10="","",LOWER(B10)&"|"&C10) -> the truman show|1998
A11: 2020-12-30 | B11: Django Unchained | C11: 2012 | D11: https://boxd.it/2cCk | E11: =IF(B11="","",LOWER(B11)&"|"&C11) -> django unchained|2012
A12: 2020-12-30 | B12: Psycho | C12: 1960 | D12: https://boxd.it/2ab2 | E12: =IF(B12="","",LOWER(B12)&"|"&C12) -> psycho|1960
A13: 2020-12-30 | B13: Psycho II | C13: 1983 | D13: https://boxd.it/1VUQ | E13: =IF(B13="","",LOWER(B13)&"|"&C13) -> psycho ii|1983
... A372: 2021-12-12 | B372: National Lampoon's Christmas Vacation | C372: 1989 | D372: https://boxd.it/22wQ | E372: =IF(B372="","",LOWER(B372)&"|"&C372) -> national lampoon's christmas vacation|1989
A373: 2021-12-14 | B373: all night | D373: https://boxd.it/xZxq | E373: =IF(B373="","",LOWER(B373)&"|"&C373) -> all night|
A374: 2021-12-14 | B374: Falling Down | C374: 1993 | D374: https://boxd.it/194M | E374: =IF(B374="","",LOWER(B374)&"|"&C374) -> falling down|1993
A375: 2021-12-14 | B375: The Polar Express | C375: 2004 | D375: https://boxd.it/23am | E375: =IF(B375="","",LOWER(B375)&"|"&C375) -> the polar express|2004
A376: 2021-12-15 | B376: Jaws | C376: 1975 | D376: https://boxd.it/2a5e | E376: =IF(B376="","",LOWER(B376)&"|"&C376) -> jaws|1975
A377: 2021-12-16 | B377: Frankenweenie | C377: 2012 | D377: https://boxd.it/bPS | E377: =IF(B377="","",LOWER(B377)&"|"&C377) -> frankenweenie|2012
A378: 2021-12-17 | B378: Home Alone | C378: 1990 | D378: https://boxd.it/29Fg | E378: =IF(B378="","",LOWER(B378)&"|"&C378) -> home alone|1990
A379: 2021-12-18 | B379: Last Days | C379: 2005 | D379: https://boxd.it/28lY | E379: =IF(B379="","",LOWER(B379)&"|"&C379) -> last days|2005
A380: 2021-12-19 | B380: Alien | C380: 1979 | D380: https://boxd.it/2awY | E380: =IF(B380="","",LOWER(B380)&"|"&C380) -> alien|1979
A381: 2021-12-20 | B381: Batman | C381: 1989 | D381: https://boxd.it/2aIU | E381: =IF(B381="","",LOWER(B381)&"|"&C381) -> batman|1989
A382: 2021-12-21 | B382: Blade Runner | C382: 1982 | D382: https://boxd.it/2bcA | E382: =IF(B382="","",LOWER(B382)&"|"&C382) -> blade runner|1982
A383: 2021-12-22 | B383: Pee-wee's Big Adventure | C383: 1985 | D383: https://boxd.it/22Lw | E383: =IF(B383="","",LOWER(B383)&"|"&C383) -> pee-wee's big adventure|1985
A384: 2021-12-23 | B384: Thunder Road | C384: 2018 | D384: https://boxd.it/i8Hs | E384: =IF(B384="","",LOWER(B384)&"|"&C384) -> thunder road|2018
A385: 2021-12-24 | B385: Death Proof | C385: 2007 | D385: https://boxd.it/27GG | E385: =IF(B385="","",LOWER(B385)&"|"&C385) -> death proof|2007
... A943: 2026-09-17 | B943: The Myth of the American Sleepover | C943: 2010 | D943: https://boxd.it/2t9u | E943: =IF(B943="","",LOWER(B943)&"|"&C943) -> the myth of the american sleepover|2010
E944: =IF(B944="","",LOWER(B944)&"|"&C944)
E945: =IF(B945="","",LOWER(B945)&"|"&C945)
E946: =IF(B946="","",LOWER(B946)&"|"&C946)
E947: =IF(B947="","",LOWER(B947)&"|"&C947)
E948: =IF(B948="","",LOWER(B948)&"|"&C948)
E949: =IF(B949="","",LOWER(B949)&"|"&C949)
E950: =IF(B950="","",LOWER(B950)&"|"&C950)
E951: =IF(B951="","",LOWER(B951)&"|"&C951)
E952: =IF(B952="","",LOWER(B952)&"|"&C952)
E953: =IF(B953="","",LOWER(B953)&"|"&C953)
E954: =IF(B954="","",LOWER(B954)&"|"&C954)
E955: =IF(B955="","",LOWER(B955)&"|"&C955)
...
